<?xml version="1.0" ?>
<!-- =================================================================================== -->
<!-- |    This document was autogenerated by xacro from src/circle_movement/description/fox.urdf.xacro | -->
<!-- |    EDITING THIS FILE BY HAND IS NOT RECOMMENDED                                 | -->
<!-- =================================================================================== -->
<robot name="sam_bot">
  <gazebo>
    <!--plugin
            filename="gz-sim-pose-publisher-system"
            name="gz::sim::systems::PosePublisher">
            <publish_link_pose>true</publish_link_pose>
            <use_pose_vector_msg>true</use_pose_vector_msg>
            <static_publisher>true</static_publisher>
            <static_update_frequency>1</static_update_frequency>
        </plugin-->
    <!--plugin
            filename="gz-sim-odometry-publisher-system"
            name="gz::sim::systems::OdometryPublisher">
            <odom_frame>robot/odom</odom_frame>
            <robot_base_frame>robot/base_link</robot_base_frame>
            <odom_publish_frequency>50</odom_publish_frequency>
        </plugin-->
    <plugin filename="gz-sim-joint-state-publisher-system" name="gz::sim::systems::JointStatePublisher">
        </plugin>
    <plugin filename="gz-sim-diff-drive-system" name="gz::sim::systems::DiffDrive">
      <left_joint>drivewhl_l_joint</left_joint>
      <right_joint>drivewhl_r_joint</right_joint>
      <child_frame_id>fox/base_link</child_frame_id>
      <wheel_separation>0.35</wheel_separation>
      <wheel_radius>0.1</wheel_radius>
      <odom_publish_frequency>10</odom_publish_frequency>
    </plugin>
  </gazebo>
  <material name="Orange">
    <color rgba="0.9921568627450981 0.13529411764705882 0.023529411764705882 1.0"/>
  </material>
  <material name="White">
    <color rgba="1. 1. 1.0 1.0"/>
  </material>
  <material name="Black">
    <ambient> 0. 0. 0.0 0.0&quot;</ambient>
  </material>
  <!-- Robot Base -->
  <link name="base_link">
    <visual>
      <geometry>
        <box size="0.31 0.31 0.31"/>
      </geometry>
      <material name="Orange"/>
    </visual>
    <collision>
      <geometry>
        <box size="0.31 0.31 0.31"/>
      </geometry>
    </collision>
    <inertial>
      <origin rpy="1.5707963267948966 0 1.5707963267948966" xyz="0 0 0"/>
      <mass value="15"/>
      <inertia ixx="0.24025000000000002" ixy="0.0" ixz="0.0" iyy="0.24025000000000002" iyz="0.0" izz="0.24025000000000002"/>
    </inertial>
  </link>
  <!-- Robot Footprint -->
  <link name="base_footprint"/>
  <joint name="base_joint" type="fixed">
    <parent link="base_link"/>
    <child link="base_footprint"/>
    <origin rpy="0 0 0" xyz="0.0 0.0 -0.18"/>
  </joint>
  <link name="right_ear_low">
    <visual>
      <geometry>
        <box size="0.02 0.1 0.05"/>
      </geometry>
      <material name="Orange"/>
    </visual>
    <collision>
      <geometry>
        <box size="0.02 0.1 0.05"/>
      </geometry>
    </collision>
    <inertial>
      <origin rpy="1.5707963267948966 0 1.5707963267948966" xyz="0 0 0"/>
      <mass value="1"/>
      <inertia ixx="0.00024166666666666672" ixy="0.0" ixz="0.0" iyy="0.0008666666666666667" iyz="0.0" izz="0.0010416666666666669"/>
    </inertial>
  </link>
  <joint name="right_ear_low_joint" type="fixed">
    <parent link="base_link"/>
    <child link="right_ear_low"/>
    <origin rpy="0 0 0" xyz="0.0 0.1 0.18"/>
  </joint>
  <link name="left_ear_low">
    <visual>
      <geometry>
        <box size="0.02 0.1 0.05"/>
      </geometry>
      <material name="Orange"/>
    </visual>
    <collision>
      <geometry>
        <box size="0.02 0.1 0.05"/>
      </geometry>
    </collision>
    <inertial>
      <origin rpy="1.5707963267948966 0 1.5707963267948966" xyz="0 0 0"/>
      <mass value="1"/>
      <inertia ixx="0.00024166666666666672" ixy="0.0" ixz="0.0" iyy="0.0008666666666666667" iyz="0.0" izz="0.0010416666666666669"/>
    </inertial>
  </link>
  <joint name="left_ear_low_joint" type="fixed">
    <parent link="base_link"/>
    <child link="left_ear_low"/>
    <origin rpy="0 0 0" xyz="0.0 -0.1 0.18"/>
  </joint>
  <link name="right_ear_high">
    <visual>
      <geometry>
        <box size="0.02 0.06 0.04"/>
      </geometry>
      <material name="Orange"/>
    </visual>
    <collision>
      <geometry>
        <box size="0.02 0.06 0.04"/>
      </geometry>
    </collision>
    <inertial>
      <origin rpy="1.5707963267948966 0 1.5707963267948966" xyz="0 0 0"/>
      <mass value="1"/>
      <inertia ixx="0.00016666666666666666" ixy="0.0" ixz="0.0" iyy="0.0003333333333333333" iyz="0.0" izz="0.0004333333333333333"/>
    </inertial>
  </link>
  <joint name="right_ear_high_joint" type="fixed">
    <parent link="base_link"/>
    <child link="right_ear_high"/>
    <origin rpy="0 0 0" xyz="0.0 0.12000000000000001 0.22000000000000003"/>
  </joint>
  <link name="left_ear_high">
    <visual>
      <geometry>
        <box size="0.02 0.06 0.04"/>
      </geometry>
      <material name="Orange"/>
    </visual>
    <collision>
      <geometry>
        <box size="0.02 0.06 0.04"/>
      </geometry>
    </collision>
    <inertial>
      <origin rpy="1.5707963267948966 0 1.5707963267948966" xyz="0 0 0"/>
      <mass value="1"/>
      <inertia ixx="0.00016666666666666666" ixy="0.0" ixz="0.0" iyy="0.0003333333333333333" iyz="0.0" izz="0.0004333333333333333"/>
    </inertial>
  </link>
  <joint name="left_ear_high_joint" type="fixed">
    <parent link="base_link"/>
    <child link="left_ear_high"/>
    <origin rpy="0 0 0" xyz="0.0 -0.12000000000000001 0.22000000000000003"/>
  </joint>
  <link name="right_eye">
    <visual>
      <geometry>
        <box size="0.005 0.08 0.08"/>
      </geometry>
      <material name="Black"/>
    </visual>
    <collision>
      <geometry>
        <box size="0.005 0.08 0.08"/>
      </geometry>
    </collision>
    <inertial>
      <origin rpy="1.5707963267948966 0 1.5707963267948966" xyz="0 0 0"/>
      <mass value="0.1"/>
      <inertia ixx="5.354166666666667e-05" ixy="0.0" ixz="0.0" iyy="5.354166666666667e-05" iyz="0.0" izz="0.00010666666666666667"/>
    </inertial>
  </link>
  <joint name="right_eye_joint" type="fixed">
    <parent link="base_link"/>
    <child link="right_eye"/>
    <origin rpy="0 0 0" xyz="0.155 0.08 0.07500000000000001"/>
  </joint>
  <link name="left_eye">
    <visual>
      <geometry>
        <box size="0.005 0.08 0.08"/>
      </geometry>
      <material name="Black"/>
    </visual>
    <collision>
      <geometry>
        <box size="0.005 0.08 0.08"/>
      </geometry>
    </collision>
    <inertial>
      <origin rpy="1.5707963267948966 0 1.5707963267948966" xyz="0 0 0"/>
      <mass value="0.1"/>
      <inertia ixx="5.354166666666667e-05" ixy="0.0" ixz="0.0" iyy="5.354166666666667e-05" iyz="0.0" izz="0.00010666666666666667"/>
    </inertial>
  </link>
  <joint name="left_eye_joint" type="fixed">
    <parent link="base_link"/>
    <child link="left_eye"/>
    <origin rpy="0 0 0" xyz="0.155 -0.08 0.07500000000000001"/>
  </joint>
  <link name="right_eye_reflect">
    <visual>
      <geometry>
        <box size="0.0025 0.04 0.04"/>
      </geometry>
      <material name="White"/>
    </visual>
    <collision>
      <geometry>
        <box size="0.0025 0.04 0.04"/>
      </geometry>
    </collision>
    <inertial>
      <origin rpy="1.5707963267948966 0 1.5707963267948966" xyz="0 0 0"/>
      <mass value="0.1"/>
      <inertia ixx="1.3385416666666667e-05" ixy="0.0" ixz="0.0" iyy="1.3385416666666667e-05" iyz="0.0" izz="2.6666666666666667e-05"/>
    </inertial>
  </link>
  <joint name="right_eye_reflect_joint" type="fixed">
    <parent link="base_link"/>
    <child link="right_eye_reflect"/>
    <origin rpy="0 0 0" xyz="0.15875 0.06 0.095"/>
  </joint>
  <link name="left_eye_reflect">
    <visual>
      <geometry>
        <box size="0.0025 0.04 0.04"/>
      </geometry>
      <material name="White"/>
    </visual>
    <collision>
      <geometry>
        <box size="0.0025 0.04 0.04"/>
      </geometry>
    </collision>
    <inertial>
      <origin rpy="1.5707963267948966 0 1.5707963267948966" xyz="0 0 0"/>
      <mass value="0.1"/>
      <inertia ixx="1.3385416666666667e-05" ixy="0.0" ixz="0.0" iyy="1.3385416666666667e-05" iyz="0.0" izz="2.6666666666666667e-05"/>
    </inertial>
  </link>
  <joint name="left_eye_reflect_joint" type="fixed">
    <parent link="base_link"/>
    <child link="left_eye_reflect"/>
    <origin rpy="0 0 0" xyz="0.15875 -0.1 0.095"/>
  </joint>
  <!-- Cheek -->
  <link name="cheek_big">
    <visual>
      <geometry>
        <box size="0.05 0.15 0.07"/>
      </geometry>
      <material name="White"/>
    </visual>
    <collision>
      <geometry>
        <box size="0.05 0.15 0.07"/>
      </geometry>
    </collision>
    <inertial>
      <origin rpy="1.5707963267948966 0 1.5707963267948966" xyz="0 0 0"/>
      <mass value="0.1"/>
      <inertia ixx="6.166666666666667e-05" ixy="0.0" ixz="0.0" iyy="0.00020833333333333335" iyz="0.0" izz="0.00022833333333333334"/>
    </inertial>
  </link>
  <joint name="cheek_big_joint" type="fixed">
    <parent link="base_link"/>
    <child link="cheek_big"/>
    <origin rpy="0 0 0" xyz="0.18 0. 0.0050000000000000044"/>
  </joint>
  <!-- Nose -->
  <link name="nose_long">
    <visual>
      <geometry>
        <box size="0.08 0.05 0.05"/>
      </geometry>
      <material name="White"/>
    </visual>
    <collision>
      <geometry>
        <box size="0.08 0.05 0.05"/>
      </geometry>
    </collision>
    <inertial>
      <origin rpy="1.5707963267948966 0 1.5707963267948966" xyz="0 0 0"/>
      <mass value="0.1"/>
      <inertia ixx="7.416666666666668e-05" ixy="0.0" ixz="0.0" iyy="7.416666666666668e-05" iyz="0.0" izz="4.166666666666667e-05"/>
    </inertial>
  </link>
  <joint name="nose_long_joint" type="fixed">
    <parent link="base_link"/>
    <child link="nose_long"/>
    <origin rpy="0 0 0" xyz="0.23333333333333334 0. 6.938893903907228e-18"/>
  </joint>
  <link name="nose">
    <visual>
      <geometry>
        <box size="0.01 0.03 0.02"/>
      </geometry>
      <material name="Black"/>
    </visual>
    <collision>
      <geometry>
        <box size="0.01 0.03 0.02"/>
      </geometry>
    </collision>
    <inertial>
      <origin rpy="1.5707963267948966 0 1.5707963267948966" xyz="0 0 0"/>
      <mass value="0.1"/>
      <inertia ixx="4.166666666666667e-06" ixy="0.0" ixz="0.0" iyy="8.333333333333334e-06" iyz="0.0" izz="1.0833333333333334e-05"/>
    </inertial>
  </link>
  <joint name="nose_joint" type="fixed">
    <parent link="base_link"/>
    <child link="nose"/>
    <origin rpy="0 0 0" xyz="0.278 0. 6.938893903907228e-18"/>
  </joint>
  <link name="drivewhl_l_link">
    <visual>
      <origin rpy="1.5707963267948966 0 0" xyz="0 0 0"/>
      <geometry>
        <cylinder length="0.04" radius="0.1"/>
      </geometry>
      <material name="Cyan">
        <color rgba="0.5 0.5 0.5 1.0"/>
      </material>
    </visual>
    <collision>
      <origin rpy="1.5707963267948966 0 0" xyz="0 0 0"/>
      <geometry>
        <cylinder length="0.04" radius="0.1"/>
      </geometry>
    </collision>
    <inertial>
      <origin rpy="1.5707963267948966 0 0" xyz="0 0 0"/>
      <mass value="0.5"/>
      <inertia ixx="0.0013166666666666667" ixy="0" ixz="0" iyy="0.0013166666666666667" iyz="0" izz="0.0025000000000000005"/>
    </inertial>
  </link>
  <joint name="drivewhl_l_joint" type="continuous">
    <parent link="base_link"/>
    <child link="drivewhl_l_link"/>
    <origin rpy="0 0 0" xyz="-0.12 0.18 -0.08"/>
    <axis xyz="0 1 0"/>
  </joint>
  <link name="drivewhl_r_link">
    <visual>
      <origin rpy="1.5707963267948966 0 0" xyz="0 0 0"/>
      <geometry>
        <cylinder length="0.04" radius="0.1"/>
      </geometry>
      <material name="Cyan">
        <color rgba="0.5 0.5 0.5 1.0"/>
      </material>
    </visual>
    <collision>
      <origin rpy="1.5707963267948966 0 0" xyz="0 0 0"/>
      <geometry>
        <cylinder length="0.04" radius="0.1"/>
      </geometry>
    </collision>
    <inertial>
      <origin rpy="1.5707963267948966 0 0" xyz="0 0 0"/>
      <mass value="0.5"/>
      <inertia ixx="0.0013166666666666667" ixy="0" ixz="0" iyy="0.0013166666666666667" iyz="0" izz="0.0025000000000000005"/>
    </inertial>
  </link>
  <joint name="drivewhl_r_joint" type="continuous">
    <parent link="base_link"/>
    <child link="drivewhl_r_link"/>
    <origin rpy="0 0 0" xyz="-0.12 -0.18 -0.08"/>
    <axis xyz="0 1 0"/>
  </joint>
  <!-- Caster Wheel -->
  <link name="front_caster">
    <visual>
      <geometry>
        <sphere radius="0.024999999999999994"/>
      </geometry>
      <material name="Cyan">
        <color rgba="0 1.0 1.0 1.0"/>
      </material>
    </visual>
    <collision>
      <origin rpy="0 0 0" xyz="0 0 0"/>
      <geometry>
        <sphere radius="0.024999999999999994"/>
      </geometry>
    </collision>
    <inertial>
      <mass value="0.5"/>
      <inertia ixx="0.00012499999999999995" ixy="0.0" ixz="0.0" iyy="0.00012499999999999995" iyz="0.0" izz="0.00012499999999999995"/>
    </inertial>
  </link>
  <joint name="caster_joint" type="fixed">
    <parent link="base_link"/>
    <child link="front_caster"/>
    <origin rpy="0 0 0" xyz="0.11 0.0 -0.155"/>
  </joint>
</robot>
